<sdf version='1.7'>
  <model name='rr_swerve'>
    <link name='base_link'>
      <inertial>
        <pose>0 0 0.193327 0 -0 0</pose>
        <mass>5.68</mass>
        <inertia>
          <ixx>0.128304</ixx>
          <ixy>0</ixy>
          <ixz>0</ixz>
          <iyy>0.128304</iyy>
          <iyz>0</iyz>
          <izz>0.127417</izz>
        </inertia>
      </inertial>
      <collision name='base_link_fixed_joint_lump__body_collision'>
        <pose>0 0 0.195 0 -0 0</pose>
        <geometry>
          <box>
            <size>0.3515 0.3515 0.3515</size>
          </box>
        </geometry>
      </collision>
      <collision name='base_link_fixed_joint_lump__imu_link_collision_1'>
        <pose>0 0 0.1 0 -0 0</pose>
        <geometry>
          <box>
            <size>0.1 0.1 0.1</size>
          </box>
        </geometry>
      </collision>
      <collision name='base_link_fixed_joint_lump__rplidar_link_collision_2'>
        <pose>0.205 0 0.04 0 -0 0</pose>
        <geometry>
          <cylinder>
            <length>0.06</length>
            <radius>0.02</radius>
          </cylinder>
        </geometry>
      </collision>
      <visual name='base_link_fixed_joint_lump__body_visual'>
        <pose>0 0 0.195 0 -0 0</pose>
        <geometry>
          <box>
            <size>0.37 0.37 0.37</size>
          </box>
        </geometry>
      </visual>
      <visual name='base_link_fixed_joint_lump__imu_link_visual_1'>
        <pose>0 0 0.1 0 -0 0</pose>
        <geometry>
          <box>
            <size>0.1 0.1 0.1</size>
          </box>
        </geometry>
      </visual>
      <visual name='base_link_fixed_joint_lump__rplidar_link_visual_2'>
        <pose>0.205 0 0.04 0 -0 0</pose>
        <geometry>
          <cylinder>
            <length>0.06</length>
            <radius>0.02</radius>
          </cylinder>
        </geometry>
      </visual>
    </link>
    <joint name='wheel_lb_angular_joint' type='revolute'>
      <pose relative_to='base_link'>-0.22 0.22 0.085 1.5708 -0 0</pose>
      <parent>base_link</parent>
      <child>wheel_lb_round_table</child>
      <axis>
        <xyz>0 1 0</xyz>
        <limit>
          <effort>6</effort>
          <velocity>12</velocity>
          <lower>-1e+16</lower>
          <upper>1e+16</upper>
        </limit>
        <dynamics>
          <damping>0.1</damping>
          <friction>0</friction>
          <spring_reference>0</spring_reference>
          <spring_stiffness>0</spring_stiffness>
        </dynamics>
      </axis>
    </joint>
    <link name='wheel_lb_round_table'>
      <pose relative_to='wheel_lb_angular_joint'>0 0 0 0 -0 0</pose>
      <inertial>
        <pose>0 0 0 0 -0 0</pose>
        <mass>0.1</mass>
        <inertia>
          <ixx>2.16667e-05</ixx>
          <ixy>0</ixy>
          <ixz>0</ixz>
          <iyy>4.16667e-05</iyy>
          <iyz>0</iyz>
          <izz>2.16667e-05</izz>
        </inertia>
      </inertial>
      <collision name='wheel_lb_round_table_collision'>
        <pose>0 0 0 0 -0 0</pose>
        <geometry>
          <box>
            <size>0.0475 0.0095 0.0475</size>
          </box>
        </geometry>
      </collision>
      <visual name='wheel_lb_round_table_visual'>
        <pose>0 0 0 0 -0 0</pose>
        <geometry>
          <box>
            <size>0.05 0.01 0.05</size>
          </box>
        </geometry>
      </visual>
    </link>
    <joint name='wheel_lb_joint' type='revolute'>
      <pose relative_to='wheel_lb_round_table'>0 -0.05 0 0 1.5708 0</pose>
      <parent>wheel_lb_round_table</parent>
      <child>wheel_lb</child>
      <axis>
        <xyz>0 0 -1</xyz>
        <limit>
          <effort>6</effort>
          <velocity>60</velocity>
          <lower>-1e+16</lower>
          <upper>1e+16</upper>
        </limit>
        <dynamics>
          <damping>0.1</damping>
          <friction>0</friction>
          <spring_reference>0</spring_reference>
          <spring_stiffness>0</spring_stiffness>
        </dynamics>
      </axis>
    </joint>
    <link name='wheel_lb'>
      <pose relative_to='wheel_lb_joint'>0 0 0 0 -0 0</pose>
      <inertial>
        <pose>0 0 0 0 -0 0</pose>
        <mass>0.5</mass>
        <inertia>
          <ixx>0.000257292</ixx>
          <ixy>0</ixy>
          <ixz>0</ixz>
          <iyy>0.000257292</iyy>
          <iyz>0</iyz>
          <izz>0.00030625</izz>
        </inertia>
      </inertial>
      <collision name='wheel_lb_collision'>
        <pose>0 0 0 0 -0 0</pose>
        <geometry>
          <cylinder>
            <length>0.05</length>
            <radius>0.035</radius>
          </cylinder>
        </geometry>
      </collision>
      <visual name='wheel_lb_visual'>
        <pose>0 0 0 0 -0 0</pose>
        <geometry>
          <cylinder>
            <length>0.05</length>
            <radius>0.035</radius>
          </cylinder>
        </geometry>
      </visual>
    </link>
    <joint name='wheel_lf_angular_joint' type='revolute'>
      <pose relative_to='base_link'>0.22 0.22 0.085 1.5708 -0 0</pose>
      <parent>base_link</parent>
      <child>wheel_lf_round_table</child>
      <axis>
        <xyz>0 1 0</xyz>
        <limit>
          <effort>6</effort>
          <velocity>12</velocity>
          <lower>-1e+16</lower>
          <upper>1e+16</upper>
        </limit>
        <dynamics>
          <damping>0.1</damping>
          <friction>0</friction>
          <spring_reference>0</spring_reference>
          <spring_stiffness>0</spring_stiffness>
        </dynamics>
      </axis>
    </joint>
    <link name='wheel_lf_round_table'>
      <pose relative_to='wheel_lf_angular_joint'>0 0 0 0 -0 0</pose>
      <inertial>
        <pose>0 0 0 0 -0 0</pose>
        <mass>0.1</mass>
        <inertia>
          <ixx>2.16667e-05</ixx>
          <ixy>0</ixy>
          <ixz>0</ixz>
          <iyy>4.16667e-05</iyy>
          <iyz>0</iyz>
          <izz>2.16667e-05</izz>
        </inertia>
      </inertial>
      <collision name='wheel_lf_round_table_collision'>
        <pose>0 0 0 0 -0 0</pose>
        <geometry>
          <box>
            <size>0.0475 0.0095 0.0475</size>
          </box>
        </geometry>
      </collision>
      <visual name='wheel_lf_round_table_visual'>
        <pose>0 0 0 0 -0 0</pose>
        <geometry>
          <box>
            <size>0.05 0.01 0.05</size>
          </box>
        </geometry>
      </visual>
    </link>
    <joint name='wheel_lf_joint' type='revolute'>
      <pose relative_to='wheel_lf_round_table'>0 -0.05 0 0 1.5708 0</pose>
      <parent>wheel_lf_round_table</parent>
      <child>wheel_lf</child>
      <axis>
        <xyz>0 0 -1</xyz>
        <limit>
          <effort>6</effort>
          <velocity>60</velocity>
          <lower>-1e+16</lower>
          <upper>1e+16</upper>
        </limit>
        <dynamics>
          <damping>0.1</damping>
          <friction>0</friction>
          <spring_reference>0</spring_reference>
          <spring_stiffness>0</spring_stiffness>
        </dynamics>
      </axis>
    </joint>
    <link name='wheel_lf'>
      <pose relative_to='wheel_lf_joint'>0 0 0 0 -0 0</pose>
      <inertial>
        <pose>0 0 0 0 -0 0</pose>
        <mass>0.5</mass>
        <inertia>
          <ixx>0.000257292</ixx>
          <ixy>0</ixy>
          <ixz>0</ixz>
          <iyy>0.000257292</iyy>
          <iyz>0</iyz>
          <izz>0.00030625</izz>
        </inertia>
      </inertial>
      <collision name='wheel_lf_collision'>
        <pose>0 0 0 0 -0 0</pose>
        <geometry>
          <cylinder>
            <length>0.05</length>
            <radius>0.035</radius>
          </cylinder>
        </geometry>
      </collision>
      <visual name='wheel_lf_visual'>
        <pose>0 0 0 0 -0 0</pose>
        <geometry>
          <cylinder>
            <length>0.05</length>
            <radius>0.035</radius>
          </cylinder>
        </geometry>
      </visual>
    </link>
    <joint name='wheel_rb_angular_joint' type='revolute'>
      <pose relative_to='base_link'>-0.22 -0.22 0.085 1.5708 -0 0</pose>
      <parent>base_link</parent>
      <child>wheel_rb_round_table</child>
      <axis>
        <xyz>0 1 0</xyz>
        <limit>
          <effort>6</effort>
          <velocity>12</velocity>
          <lower>-1e+16</lower>
          <upper>1e+16</upper>
        </limit>
        <dynamics>
          <damping>0.1</damping>
          <friction>0</friction>
          <spring_reference>0</spring_reference>
          <spring_stiffness>0</spring_stiffness>
        </dynamics>
      </axis>
    </joint>
    <link name='wheel_rb_round_table'>
      <pose relative_to='wheel_rb_angular_joint'>0 0 0 0 -0 0</pose>
      <inertial>
        <pose>0 0 0 0 -0 0</pose>
        <mass>0.1</mass>
        <inertia>
          <ixx>2.16667e-05</ixx>
          <ixy>0</ixy>
          <ixz>0</ixz>
          <iyy>4.16667e-05</iyy>
          <iyz>0</iyz>
          <izz>2.16667e-05</izz>
        </inertia>
      </inertial>
      <collision name='wheel_rb_round_table_collision'>
        <pose>0 0 0 0 -0 0</pose>
        <geometry>
          <box>
            <size>0.0475 0.0095 0.0475</size>
          </box>
        </geometry>
      </collision>
      <visual name='wheel_rb_round_table_visual'>
        <pose>0 0 0 0 -0 0</pose>
        <geometry>
          <box>
            <size>0.05 0.01 0.05</size>
          </box>
        </geometry>
      </visual>
    </link>
    <joint name='wheel_rb_joint' type='revolute'>
      <pose relative_to='wheel_rb_round_table'>0 -0.05 0 0 1.5708 0</pose>
      <parent>wheel_rb_round_table</parent>
      <child>wheel_rb</child>
      <axis>
        <xyz>0 0 -1</xyz>
        <limit>
          <effort>6</effort>
          <velocity>60</velocity>
          <lower>-1e+16</lower>
          <upper>1e+16</upper>
        </limit>
        <dynamics>
          <damping>0.1</damping>
          <friction>0</friction>
          <spring_reference>0</spring_reference>
          <spring_stiffness>0</spring_stiffness>
        </dynamics>
      </axis>
    </joint>
    <link name='wheel_rb'>
      <pose relative_to='wheel_rb_joint'>0 0 0 0 -0 0</pose>
      <inertial>
        <pose>0 0 0 0 -0 0</pose>
        <mass>0.5</mass>
        <inertia>
          <ixx>0.000257292</ixx>
          <ixy>0</ixy>
          <ixz>0</ixz>
          <iyy>0.000257292</iyy>
          <iyz>0</iyz>
          <izz>0.00030625</izz>
        </inertia>
      </inertial>
      <collision name='wheel_rb_collision'>
        <pose>0 0 0 0 -0 0</pose>
        <geometry>
          <cylinder>
            <length>0.05</length>
            <radius>0.035</radius>
          </cylinder>
        </geometry>
      </collision>
      <visual name='wheel_rb_visual'>
        <pose>0 0 0 0 -0 0</pose>
        <geometry>
          <cylinder>
            <length>0.05</length>
            <radius>0.035</radius>
          </cylinder>
        </geometry>
      </visual>
    </link>
    <joint name='wheel_rf_angular_joint' type='revolute'>
      <pose relative_to='base_link'>0.22 -0.22 0.085 1.5708 -0 0</pose>
      <parent>base_link</parent>
      <child>wheel_rf_round_table</child>
      <axis>
        <xyz>0 1 0</xyz>
        <limit>
          <effort>6</effort>
          <velocity>12</velocity>
          <lower>-1e+16</lower>
          <upper>1e+16</upper>
        </limit>
        <dynamics>
          <damping>0.1</damping>
          <friction>0</friction>
          <spring_reference>0</spring_reference>
          <spring_stiffness>0</spring_stiffness>
        </dynamics>
      </axis>
    </joint>
    <link name='wheel_rf_round_table'>
      <pose relative_to='wheel_rf_angular_joint'>0 0 0 0 -0 0</pose>
      <inertial>
        <pose>0 0 0 0 -0 0</pose>
        <mass>0.1</mass>
        <inertia>
          <ixx>2.16667e-05</ixx>
          <ixy>0</ixy>
          <ixz>0</ixz>
          <iyy>4.16667e-05</iyy>
          <iyz>0</iyz>
          <izz>2.16667e-05</izz>
        </inertia>
      </inertial>
      <collision name='wheel_rf_round_table_collision'>
        <pose>0 0 0 0 -0 0</pose>
        <geometry>
          <box>
            <size>0.0475 0.0095 0.0475</size>
          </box>
        </geometry>
      </collision>
      <visual name='wheel_rf_round_table_visual'>
        <pose>0 0 0 0 -0 0</pose>
        <geometry>
          <box>
            <size>0.05 0.01 0.05</size>
          </box>
        </geometry>
      </visual>
    </link>
    <joint name='wheel_rf_joint' type='revolute'>
      <pose relative_to='wheel_rf_round_table'>0 -0.05 0 0 1.5708 0</pose>
      <parent>wheel_rf_round_table</parent>
      <child>wheel_rf</child>
      <axis>
        <xyz>0 0 -1</xyz>
        <limit>
          <effort>6</effort>
          <velocity>60</velocity>
          <lower>-1e+16</lower>
          <upper>1e+16</upper>
        </limit>
        <dynamics>
          <damping>0.1</damping>
          <friction>0</friction>
          <spring_reference>0</spring_reference>
          <spring_stiffness>0</spring_stiffness>
        </dynamics>
      </axis>
    </joint>
    <link name='wheel_rf'>
      <pose relative_to='wheel_rf_joint'>0 0 0 0 -0 0</pose>
      <inertial>
        <pose>0 0 0 0 -0 0</pose>
        <mass>0.5</mass>
        <inertia>
          <ixx>0.000257292</ixx>
          <ixy>0</ixy>
          <ixz>0</ixz>
          <iyy>0.000257292</iyy>
          <iyz>0</iyz>
          <izz>0.00030625</izz>
        </inertia>
      </inertial>
      <collision name='wheel_rf_collision'>
        <pose>0 0 0 0 -0 0</pose>
        <geometry>
          <cylinder>
            <length>0.05</length>
            <radius>0.035</radius>
          </cylinder>
        </geometry>
      </collision>
      <visual name='wheel_rf_visual'>
        <pose>0 0 0 0 -0 0</pose>
        <geometry>
          <cylinder>
            <length>0.05</length>
            <radius>0.035</radius>
          </cylinder>
        </geometry>
      </visual>
    </link>
  </model>
</sdf>
