<?xml version="1.0" ?>
<!-- =================================================================================== -->
<!-- |    This document was autogenerated by xacro from swerve_robot.urdf.xacro        | -->
<!-- |    EDITING THIS FILE BY HAND IS NOT RECOMMENDED                                 | -->
<!-- =================================================================================== -->
<robot name="rr_swerve">
  <link name="base_link"/>
  <link name="body">
    <visual>
      <geometry>
        <box size="0.37 0.37 0.37"/>
      </geometry>
    </visual>
    <collision>
      <geometry>
        <box size="0.3515 0.3515 0.3515"/>
      </geometry>
    </collision>
    <inertial>
      <origin rpy="0 0 0" xyz="0 0 0"/>
      <mass value="5.58"/>
      <inertia ixx="0.127317" ixy="0" ixz="0" iyx="0" iyy="0.127317" iyz="0" izx="0" izy="0" izz="0.127317"/>
    </inertial>
  </link>
  <joint name="base_body_joint" type="fixed">
    <parent link="base_link"/>
    <child link="body"/>
    <origin rpy="0 0 0" xyz="0 0 0.195"/>
  </joint>
  <link name="wheel_rf_round_table">
    <visual>
      <geometry>
        <box size="0.05 0.01 0.05"/>
      </geometry>
    </visual>
    <collision>
      <geometry>
        <box size="0.0475 0.0095 0.0475"/>
      </geometry>
    </collision>
    <inertial>
      <origin rpy="0 0 0" xyz="0 0 0"/>
      <mass value="0.1"/>
      <inertia ixx="2.166666666666667e-05" ixy="0" ixz="0" iyx="0" iyy="4.166666666666667e-05" iyz="0" izx="0" izy="0" izz="2.166666666666667e-05"/>
    </inertial>
  </link>
  <link name="wheel_rf">
    <visual>
      <geometry>
        <cylinder length="0.05" radius="0.035"/>
      </geometry>
    </visual>
    <collision>
      <geometry>
        <cylinder length="0.05" radius="0.035"/>
      </geometry>
      <surface>
        <friction>
          <ode>
            <mu>1</mu>
            <mu2>1</mu2>
            <slip1>0.035</slip1>
            <slip2>0</slip2>
            <fdir1>0 0 1</fdir1>
          </ode>
        </friction>
      </surface>
    </collision>
    <inertial>
      <origin rpy="0 0 0" xyz="0 0 0"/>
      <mass value="0.5"/>
      <inertia ixx="0.00025729166666666674" ixy="0" ixz="0" iyx="0" iyy="0.00025729166666666674" iyz="0" izx="0" izy="0" izz="0.00030625000000000004"/>
    </inertial>
  </link>
  <joint name="wheel_rf_joint" type="continuous">
    <parent link="wheel_rf_round_table"/>
    <child link="wheel_rf"/>
    <origin rpy="0 1.5707963267948966 0" xyz="0.0 -0.05 0.0"/>
    <!--z: position from base_link - position from body-->
    <axis xyz="0 0 -1"/>
    <limit effort="6.0" velocity="60.0"/>
    <!-- maximum torqe(<8.82), maximum velocity-->
    <dynamics damping="0.1"/>
  </joint>
  <joint name="wheel_rf_angular_joint" type="continuous">
    <parent link="base_link"/>
    <child link="wheel_rf_round_table"/>
    <origin rpy="1.5707963267948966 0 0" xyz="0.22 -0.22 0.085"/>
    <!--z: position from base_link - position from body-->
    <axis xyz="0 1 0"/>
    <limit effort="6.0" velocity="12.0"/>
    <!-- maximum torqe(<8.82), maximum velocity-->
    <dynamics damping="0.1"/>
  </joint>
  <plugin filename="gz-sim-joint-controller-system" name="gz::sim::systems::JointController">
    <joint_name>wheel_rf_angular_joint</joint_name>
    <initial_velocity>5.0</initial_velocity>
  </plugin>
  <link name="wheel_lf_round_table">
    <visual>
      <geometry>
        <box size="0.05 0.01 0.05"/>
      </geometry>
    </visual>
    <collision>
      <geometry>
        <box size="0.0475 0.0095 0.0475"/>
      </geometry>
    </collision>
    <inertial>
      <origin rpy="0 0 0" xyz="0 0 0"/>
      <mass value="0.1"/>
      <inertia ixx="2.166666666666667e-05" ixy="0" ixz="0" iyx="0" iyy="4.166666666666667e-05" iyz="0" izx="0" izy="0" izz="2.166666666666667e-05"/>
    </inertial>
  </link>
  <link name="wheel_lf">
    <visual>
      <geometry>
        <cylinder length="0.05" radius="0.035"/>
      </geometry>
    </visual>
    <collision>
      <geometry>
        <cylinder length="0.05" radius="0.035"/>
      </geometry>
      <surface>
        <friction>
          <ode>
            <mu>1</mu>
            <mu2>1</mu2>
            <slip1>0.035</slip1>
            <slip2>0</slip2>
            <fdir1>0 0 1</fdir1>
          </ode>
        </friction>
      </surface>
    </collision>
    <inertial>
      <origin rpy="0 0 0" xyz="0 0 0"/>
      <mass value="0.5"/>
      <inertia ixx="0.00025729166666666674" ixy="0" ixz="0" iyx="0" iyy="0.00025729166666666674" iyz="0" izx="0" izy="0" izz="0.00030625000000000004"/>
    </inertial>
  </link>
  <joint name="wheel_lf_joint" type="continuous">
    <parent link="wheel_lf_round_table"/>
    <child link="wheel_lf"/>
    <origin rpy="0 1.5707963267948966 0" xyz="0.0 -0.05 0.0"/>
    <!--z: position from base_link - position from body-->
    <axis xyz="0 0 -1"/>
    <limit effort="6.0" velocity="60.0"/>
    <!-- maximum torqe(<8.82), maximum velocity-->
    <dynamics damping="0.1"/>
  </joint>
  <joint name="wheel_lf_angular_joint" type="continuous">
    <parent link="base_link"/>
    <child link="wheel_lf_round_table"/>
    <origin rpy="1.5707963267948966 0 0" xyz="0.22 0.22 0.085"/>
    <axis xyz="0 1 0"/>
    <limit effort="6.0" velocity="12.0"/>
    <!-- maximum torqe(<8.82), maximum velocity-->
    <dynamics damping="0.1"/>
  </joint>
  <plugin filename="gz-sim-joint-controller-system" name="gz::sim::systems::JointController">
    <joint_name>wheel_lf_angular_joint</joint_name>
    <initial_velocity>5.0</initial_velocity>
  </plugin>
  <link name="wheel_rb_round_table">
    <visual>
      <geometry>
        <box size="0.05 0.01 0.05"/>
      </geometry>
    </visual>
    <collision>
      <geometry>
        <box size="0.0475 0.0095 0.0475"/>
      </geometry>
    </collision>
    <inertial>
      <origin rpy="0 0 0" xyz="0 0 0"/>
      <mass value="0.1"/>
      <inertia ixx="2.166666666666667e-05" ixy="0" ixz="0" iyx="0" iyy="4.166666666666667e-05" iyz="0" izx="0" izy="0" izz="2.166666666666667e-05"/>
    </inertial>
  </link>
  <link name="wheel_rb">
    <visual>
      <geometry>
        <cylinder length="0.05" radius="0.035"/>
      </geometry>
    </visual>
    <collision>
      <geometry>
        <cylinder length="0.05" radius="0.035"/>
      </geometry>
      <surface>
        <friction>
          <ode>
            <mu>1</mu>
            <mu2>1</mu2>
            <slip1>0.035</slip1>
            <slip2>0</slip2>
            <fdir1>0 0 1</fdir1>
          </ode>
        </friction>
      </surface>
    </collision>
    <inertial>
      <origin rpy="0 0 0" xyz="0 0 0"/>
      <mass value="0.5"/>
      <inertia ixx="0.00025729166666666674" ixy="0" ixz="0" iyx="0" iyy="0.00025729166666666674" iyz="0" izx="0" izy="0" izz="0.00030625000000000004"/>
    </inertial>
  </link>
  <joint name="wheel_rb_joint" type="continuous">
    <parent link="wheel_rb_round_table"/>
    <child link="wheel_rb"/>
    <origin rpy="0 1.5707963267948966 0" xyz="0.0 -0.05 0.0"/>
    <!--z: position from base_link - position from body-->
    <axis xyz="0 0 -1"/>
    <limit effort="6.0" velocity="60.0"/>
    <!-- maximum torqe(<8.82), maximum velocity-->
    <dynamics damping="0.1"/>
  </joint>
  <joint name="wheel_rb_angular_joint" type="continuous">
    <parent link="base_link"/>
    <child link="wheel_rb_round_table"/>
    <origin rpy="1.5707963267948966 0 0" xyz="-0.22 -0.22 0.085"/>
    <!--z: position from base_link - position from body-->
    <axis xyz="0 1 0"/>
    <limit effort="6.0" velocity="12.0"/>
    <!-- maximum torqe(<8.82), maximum velocity-->
    <dynamics damping="0.1"/>
  </joint>
  <plugin filename="gz-sim-joint-controller-system" name="gz::sim::systems::JointController">
    <joint_name>wheel_rb_angular_joint</joint_name>
    <initial_velocity>5.0</initial_velocity>
  </plugin>
  <link name="wheel_lb_round_table">
    <visual>
      <geometry>
        <box size="0.05 0.01 0.05"/>
      </geometry>
    </visual>
    <collision>
      <geometry>
        <box size="0.0475 0.0095 0.0475"/>
      </geometry>
    </collision>
    <inertial>
      <origin rpy="0 0 0" xyz="0 0 0"/>
      <mass value="0.1"/>
      <inertia ixx="2.166666666666667e-05" ixy="0" ixz="0" iyx="0" iyy="4.166666666666667e-05" iyz="0" izx="0" izy="0" izz="2.166666666666667e-05"/>
    </inertial>
  </link>
  <link name="wheel_lb">
    <visual>
      <geometry>
        <cylinder length="0.05" radius="0.035"/>
      </geometry>
    </visual>
    <collision>
      <geometry>
        <cylinder length="0.05" radius="0.035"/>
      </geometry>
      <surface>
        <friction>
          <ode>
            <mu>1</mu>
            <mu2>1</mu2>
            <slip1>0.035</slip1>
            <slip2>0</slip2>
            <fdir1>0 0 1</fdir1>
          </ode>
        </friction>
      </surface>
    </collision>
    <inertial>
      <origin rpy="0 0 0" xyz="0 0 0"/>
      <mass value="0.5"/>
      <inertia ixx="0.00025729166666666674" ixy="0" ixz="0" iyx="0" iyy="0.00025729166666666674" iyz="0" izx="0" izy="0" izz="0.00030625000000000004"/>
    </inertial>
  </link>
  <joint name="wheel_lb_joint" type="continuous">
    <parent link="wheel_lb_round_table"/>
    <child link="wheel_lb"/>
    <origin rpy="0 1.5707963267948966 0" xyz="0.0 -0.05 0.0"/>
    <!--z: position from base_link - position from body-->
    <axis xyz="0 0 -1"/>
    <limit effort="6.0" velocity="60.0"/>
    <!-- maximum torqe(<8.82), maximum velocity-->
    <dynamics damping="0.1"/>
  </joint>
  <joint name="wheel_lb_angular_joint" type="continuous">
    <parent link="base_link"/>
    <child link="wheel_lb_round_table"/>
    <origin rpy="1.5707963267948966 0 0" xyz="-0.22 0.22 0.085"/>
    <axis xyz="0 1 0"/>
    <limit effort="6.0" velocity="12.0"/>
    <!-- maximum torqe(<8.82), maximum velocity-->
    <dynamics damping="0.1"/>
  </joint>
  <plugin filename="gz-sim-joint-controller-system" name="gz::sim::systems::JointController">
    <joint_name>wheel_lb_angular_joint</joint_name>
    <initial_velocity>5.0</initial_velocity>
  </plugin>
  <joint name="rplidar_joint" type="fixed">
    <parent link="base_link"/>
    <child link="rplidar_link"/>
    <origin rpy="0 0 0" xyz="0.205 0 0.04"/>
  </joint>
  <link name="rplidar_link">
    <visual>
      <origin rpy="0 0 0" xyz="0 0 0"/>
      <geometry>
        <cylinder length="0.06" radius="0.02"/>
      </geometry>
    </visual>
    <collision>
      <origin rpy="0 0 0" xyz="0 0 0"/>
      <geometry>
        <cylinder length="0.06" radius="0.02"/>
      </geometry>
    </collision>
    <sensor name="rplidar" type="gpu_lidar">
      <pose>0 0 0 0 0 0</pose>
      <visualize>false</visualize>
      <update_rate>10</update_rate>
      <lidar>
        <scan>
          <horizontal>
            <samples>400</samples>
            <resolution>1</resolution>
            <min_angle>-3.141592653589793</min_angle>
            <max_angle>3.141592653589793</max_angle>
          </horizontal>
        </scan>
        <range>
          <min>0.10</min>
          <max>20.0</max>
          <resolution>0.01</resolution>
        </range>
        <noise>
          <type>gaussian</type>
          <mean>0.0</mean>
          <stddev>0.01</stddev>
        </noise>
      </lidar>
    </sensor>
  </link>
  <plugin filename="libignition-gazebo-imu-system.so" name="ignition::gazebo::systems::Imu">
        </plugin>
  <joint name="imu_joint" type="fixed">
    <parent link="base_link"/>
    <child link="imu_link"/>
    <origin rpy="0 0 0" xyz="0.0 0 0.10"/>
  </joint>
  <link name="imu_link">
    <visual>
      <geometry>
        <box size="0.1 0.1 0.1"/>
      </geometry>
    </visual>
    <collision>
      <geometry>
        <box size="0.1 0.1 0.1"/>
      </geometry>
    </collision>
    <inertial>
      <origin rpy="0 0 0" xyz="0 0 0"/>
      <mass value="0.1"/>
      <inertia ixx="0.0001" ixy="0" ixz="0" iyx="0" iyy="0.0001" iyz="0" izx="0" izy="0" izz="0.0001"/>
    </inertial>
    <sensor name="imu_sensor" type="imu">
      <always_on>true</always_on>
      <update_rate>100</update_rate>
      <visualize>true</visualize>
      <topic>imu</topic>
      <pose>0 0 0 0 0 0</pose>
    </sensor>
  </link>
</robot>
